
[2017-12-08 16:39:53] Traceback (most recent call last):

  File "javascript_dialog_handler.pyx", line 109, in cefpython_py27.JavascriptDialogHandler_OnResetJavascriptDialogState (cefpython.cpp:75136)

  File "C:\MMELC_pilot\python\wxpython_viewer.py", line 1075, in OnResetJavascriptDialogState
    print("[wxpython_viewer.py] OnResetDialogState()")

IOError: [Errno 9] Bad file descriptor


[2017-12-08 17:05:05] Traceback (most recent call last):

  File "v8function_handler_cef3.pyx", line 39, in cefpython_py27.V8FunctionHandler_Execute (cefpython.cpp:38833)

TypeError: send_error_reports() takes no arguments (1 given)


[2017-12-08 17:05:22] Traceback (most recent call last):

  File "v8function_handler_cef3.pyx", line 39, in cefpython_py27.V8FunctionHandler_Execute (cefpython.cpp:38833)

TypeError: get_updates() takes no arguments (1 given)


[2017-12-08 17:17:33] Traceback (most recent call last):

  File "v8function_handler_cef3.pyx", line 39, in cefpython_py27.V8FunctionHandler_Execute (cefpython.cpp:38833)

TypeError: send_error_reports() takes no arguments (1 given)


[2017-12-08 17:21:52] Traceback (most recent call last):

  File "v8function_handler_cef3.pyx", line 39, in cefpython_py27.V8FunctionHandler_Execute (cefpython.cpp:38833)

TypeError: send_error_reports() takes no arguments (1 given)


[2017-12-08 17:26:40] Traceback (most recent call last):

  File "v8function_handler_cef3.pyx", line 39, in cefpython_py27.V8FunctionHandler_Execute (cefpython.cpp:38833)

TypeError: send_error_reports() takes no arguments (1 given)


[2017-12-08 17:44:56] Traceback (most recent call last):

  File "v8function_handler_cef3.pyx", line 39, in cefpython_py27.V8FunctionHandler_Execute (cefpython.cpp:38833)

TypeError: send_error_reports() takes exactly 1 argument (2 given)


[2017-12-08 18:28:57] Traceback (most recent call last):

  File "v8function_handler_cef3.pyx", line 39, in cefpython_py27.V8FunctionHandler_Execute (cefpython.cpp:38833)

  File "C:\MMELC_pilot\python\wxpython_viewer.py", line 594, in send_error_reports
    loc = dirname(__file__)

NameError: global name 'dirname' is not defined


[2017-12-08 18:34:46] Traceback (most recent call last):

  File "v8function_handler_cef3.pyx", line 39, in cefpython_py27.V8FunctionHandler_Execute (cefpython.cpp:38833)

  File "C:\MMELC_pilot\python\wxpython_viewer.py", line 594, in send_error_reports
    loc = dirname(__file__)

NameError: global name 'dirname' is not defined


[2017-12-08 18:37:25] Traceback (most recent call last):

  File "v8function_handler_cef3.pyx", line 39, in cefpython_py27.V8FunctionHandler_Execute (cefpython.cpp:38833)

  File "C:\MMELC_pilot\python\wxpython_viewer.py", line 594, in send_error_reports
    loc = dirname(__file__)

NameError: global name 'dirname' is not defined


[2017-12-08 18:38:06] Traceback (most recent call last):

  File "v8function_handler_cef3.pyx", line 39, in cefpython_py27.V8FunctionHandler_Execute (cefpython.cpp:38833)

  File "C:\MMELC_pilot\python\wxpython_viewer.py", line 594, in send_error_reports
    loc = dirname(__file__)

NameError: global name 'dirname' is not defined


[2017-12-08 19:00:03] Traceback (most recent call last):

  File "v8function_handler_cef3.pyx", line 39, in cefpython_py27.V8FunctionHandler_Execute (cefpython.cpp:38833)

  File "C:\MMELC_pilot\python\wxpython_viewer.py", line 594, in send_error_reports
    loc = dirname(__file__)

NameError: global name 'dirname' is not defined


[2017-12-08 19:03:51] Traceback (most recent call last):

  File "v8function_handler_cef3.pyx", line 39, in cefpython_py27.V8FunctionHandler_Execute (cefpython.cpp:38833)

  File "C:\MMELC_pilot\python\wxpython_viewer.py", line 594, in send_error_reports
    loc = dirname(__file__)

NameError: global name 'dirname' is not defined


[2017-12-08 19:08:02] Traceback (most recent call last):

  File "v8function_handler_cef3.pyx", line 39, in cefpython_py27.V8FunctionHandler_Execute (cefpython.cpp:38833)

  File "C:\MMELC_pilot\python\wxpython_viewer.py", line 594, in send_error_reports
    loc = dirname(__file__)

NameError: global name 'dirname' is not defined


[2017-12-08 19:08:25] Traceback (most recent call last):

  File "v8function_handler_cef3.pyx", line 39, in cefpython_py27.V8FunctionHandler_Execute (cefpython.cpp:38833)

  File "C:\MMELC_pilot\python\wxpython_viewer.py", line 594, in send_error_reports
    loc = dirname(__file__)

NameError: global name 'dirname' is not defined


[2017-12-08 19:09:53] Traceback (most recent call last):

  File "v8function_handler_cef3.pyx", line 39, in cefpython_py27.V8FunctionHandler_Execute (cefpython.cpp:38833)

  File "C:\MMELC_pilot\python\wxpython_viewer.py", line 606, in send_error_reports
    files = {'zipFile' : open(file_name) }

IOError: [Errno 2] No such file or directory: 'C:\\MMELC_pilot\\python\\error_reports.zip'


[2017-12-08 19:15:45] Traceback (most recent call last):

  File "v8function_handler_cef3.pyx", line 39, in cefpython_py27.V8FunctionHandler_Execute (cefpython.cpp:38833)

  File "C:\MMELC_pilot\python\wxpython_viewer.py", line 606, in send_error_reports
    files = {'zipFile' : open(file_name) }

IOError: [Errno 2] No such file or directory: 'C:\\MMELC_pilot\\python\\error_reports.zip'


[2017-12-08 19:16:15] Traceback (most recent call last):

  File "v8function_handler_cef3.pyx", line 39, in cefpython_py27.V8FunctionHandler_Execute (cefpython.cpp:38833)

  File "C:\MMELC_pilot\python\wxpython_viewer.py", line 606, in send_error_reports
    files = {'zipFile' : open(file_name) }

IOError: [Errno 2] No such file or directory: 'C:\\MMELC_pilot\\python\\error_reports.zip'


[2017-12-08 19:18:06] Traceback (most recent call last):

  File "v8function_handler_cef3.pyx", line 39, in cefpython_py27.V8FunctionHandler_Execute (cefpython.cpp:38833)

  File "C:\MMELC_pilot\python\wxpython_viewer.py", line 618, in send_error_reports
    except Exception(e):

NameError: global name 'e' is not defined


[2017-12-08 19:18:25] Traceback (most recent call last):

  File "v8function_handler_cef3.pyx", line 39, in cefpython_py27.V8FunctionHandler_Execute (cefpython.cpp:38833)

  File "C:\MMELC_pilot\python\wxpython_viewer.py", line 606, in send_error_reports
    files = {'zipFile' : open(file_name) }

IOError: [Errno 2] No such file or directory: 'C:\\MMELC_pilot\\python\\error_reports.zip'


[2017-12-08 19:19:28] Traceback (most recent call last):

  File "v8function_handler_cef3.pyx", line 39, in cefpython_py27.V8FunctionHandler_Execute (cefpython.cpp:38833)

  File "C:\MMELC_pilot\python\wxpython_viewer.py", line 606, in send_error_reports
    files = {'zipFile' : open(file_name) }

IOError: [Errno 2] No such file or directory: 'C:\\MMELC_pilot\\python\\error_reports.zip'


[2017-12-08 19:20:09] Traceback (most recent call last):

  File "v8function_handler_cef3.pyx", line 39, in cefpython_py27.V8FunctionHandler_Execute (cefpython.cpp:38833)

  File "C:\MMELC_pilot\python\wxpython_viewer.py", line 606, in send_error_reports
    files = {'zipFile' : open(file_name) }

IOError: [Errno 2] No such file or directory: 'C:\\MMELC_pilot\\python\\error_reports.zip'


[2017-12-08 19:22:25] Traceback (most recent call last):

  File "v8function_handler_cef3.pyx", line 39, in cefpython_py27.V8FunctionHandler_Execute (cefpython.cpp:38833)

  File "C:\MMELC_pilot\python\wxpython_viewer.py", line 607, in send_error_reports
    except Exception(e):

NameError: global name 'e' is not defined


[2017-12-08 19:22:58] Traceback (most recent call last):

  File "v8function_handler_cef3.pyx", line 39, in cefpython_py27.V8FunctionHandler_Execute (cefpython.cpp:38833)

  File "C:\MMELC_pilot\python\wxpython_viewer.py", line 620, in send_error_reports
    except Exception(e):

NameError: global name 'e' is not defined


[2017-12-08 19:23:40] Traceback (most recent call last):

  File "v8function_handler_cef3.pyx", line 39, in cefpython_py27.V8FunctionHandler_Execute (cefpython.cpp:38833)

  File "C:\MMELC_pilot\python\wxpython_viewer.py", line 620, in send_error_reports
    except Exception(e):

NameError: global name 'e' is not defined


[2017-12-08 19:24:03] Traceback (most recent call last):

  File "v8function_handler_cef3.pyx", line 39, in cefpython_py27.V8FunctionHandler_Execute (cefpython.cpp:38833)

  File "C:\MMELC_pilot\python\wxpython_viewer.py", line 620, in send_error_reports
    except Exception(e):

NameError: global name 'e' is not defined


[2017-12-08 19:25:29] Traceback (most recent call last):

  File "v8function_handler_cef3.pyx", line 39, in cefpython_py27.V8FunctionHandler_Execute (cefpython.cpp:38833)

  File "C:\MMELC_pilot\python\wxpython_viewer.py", line 607, in send_error_reports
    except Exception(e):

NameError: global name 'e' is not defined


[2017-12-08 19:26:19] Traceback (most recent call last):

  File "v8function_handler_cef3.pyx", line 39, in cefpython_py27.V8FunctionHandler_Execute (cefpython.cpp:38833)

  File "C:\MMELC_pilot\python\wxpython_viewer.py", line 607, in send_error_reports
    except Exception(e):

NameError: global name 'e' is not defined


[2017-12-11 16:09:02] Traceback (most recent call last):

  File "v8function_handler_cef3.pyx", line 39, in cefpython_py27.V8FunctionHandler_Execute (cefpython.cpp:38833)

  File "C:\MMELC_pilot\python\wxpython_viewer.py", line 639, in get_updates
    except urllib2.HTTPError,e:

NameError: global name 'urllib2' is not defined


[2017-12-11 16:10:31] Traceback (most recent call last):

  File "v8function_handler_cef3.pyx", line 39, in cefpython_py27.V8FunctionHandler_Execute (cefpython.cpp:38833)

  File "C:\MMELC_pilot\python\wxpython_viewer.py", line 639, in get_updates
    except urllib2.HTTPError,e:

NameError: global name 'urllib2' is not defined


[2017-12-11 16:10:46] Traceback (most recent call last):

  File "v8function_handler_cef3.pyx", line 39, in cefpython_py27.V8FunctionHandler_Execute (cefpython.cpp:38833)

  File "C:\MMELC_pilot\python\wxpython_viewer.py", line 639, in get_updates
    except urllib2.HTTPError,e:

NameError: global name 'urllib2' is not defined


[2017-12-11 16:13:05] Traceback (most recent call last):

  File "v8function_handler_cef3.pyx", line 39, in cefpython_py27.V8FunctionHandler_Execute (cefpython.cpp:38833)

  File "C:\MMELC_pilot\python\wxpython_viewer.py", line 639, in get_updates
    except urllib2.HTTPError,e:

NameError: global name 'urllib2' is not defined


[2017-12-11 16:13:55] Traceback (most recent call last):

  File "v8function_handler_cef3.pyx", line 39, in cefpython_py27.V8FunctionHandler_Execute (cefpython.cpp:38833)

  File "C:\MMELC_pilot\python\wxpython_viewer.py", line 644, in get_updates
    jsCallBack.Call(response)

NameError: global name 'response' is not defined


[2017-12-11 16:14:40] Traceback (most recent call last):

  File "v8function_handler_cef3.pyx", line 39, in cefpython_py27.V8FunctionHandler_Execute (cefpython.cpp:38833)

  File "C:\MMELC_pilot\python\wxpython_viewer.py", line 644, in get_updates
    jsCallBack.Call(response)

NameError: global name 'response' is not defined


[2017-12-11 16:17:24] Traceback (most recent call last):

  File "v8function_handler_cef3.pyx", line 39, in cefpython_py27.V8FunctionHandler_Execute (cefpython.cpp:38833)

  File "C:\MMELC_pilot\python\wxpython_viewer.py", line 639, in get_updates
    except urllib2.HTTPError,e:

NameError: global name 'urllib2' is not defined


[2017-12-11 16:18:18] Traceback (most recent call last):

  File "v8function_handler_cef3.pyx", line 39, in cefpython_py27.V8FunctionHandler_Execute (cefpython.cpp:38833)

  File "C:\MMELC_pilot\python\wxpython_viewer.py", line 639, in get_updates
    except urllib2.HTTPError,e:

NameError: global name 'urllib2' is not defined


[2017-12-18 16:51:08] Traceback (most recent call last):

  File "v8function_handler_cef3.pyx", line 39, in cefpython_py27.V8FunctionHandler_Execute (cefpython.cpp:38833)

  File "C:\MMELC_pilot\python\wxpython_viewer.py", line 645, in get_updates
    url = get_endpoint()+'/api/v1.0/getUpdates'

NameError: global name 'get_endpoint' is not defined


[2017-12-18 16:52:49] Traceback (most recent call last):

  File "v8function_handler_cef3.pyx", line 39, in cefpython_py27.V8FunctionHandler_Execute (cefpython.cpp:38833)

  File "C:\MMELC_pilot\python\wxpython_viewer.py", line 627, in send_error_reports
    url =  get_endpoint()+'/api/v1.0/upload/'+zip_name #'http://mmelc.vestigesystems.com/putZip'

NameError: global name 'get_endpoint' is not defined


[2017-12-18 16:57:29] Traceback (most recent call last):

  File "v8function_handler_cef3.pyx", line 39, in cefpython_py27.V8FunctionHandler_Execute (cefpython.cpp:38833)

  File "C:\MMELC_pilot\python\wxpython_viewer.py", line 645, in get_updates
    url = get_endpoint()+'/api/v1.0/getUpdates'

NameError: global name 'get_endpoint' is not defined


[2017-12-18 16:58:32] Traceback (most recent call last):

  File "v8function_handler_cef3.pyx", line 39, in cefpython_py27.V8FunctionHandler_Execute (cefpython.cpp:38833)

  File "C:\MMELC_pilot\python\wxpython_viewer.py", line 645, in get_updates
    url = get_endpoint()+'/api/v1.0/getUpdates'

NameError: global name 'get_endpoint' is not defined


[2017-12-18 17:04:09] Traceback (most recent call last):

  File "v8function_handler_cef3.pyx", line 39, in cefpython_py27.V8FunctionHandler_Execute (cefpython.cpp:38833)

  File "C:\MMELC_pilot\python\wxpython_viewer.py", line 645, in get_updates
    url = get_endpoint()+'/api/v1.0/getUpdates'

NameError: global name 'get_endpoint' is not defined


[2017-12-18 17:07:04] Traceback (most recent call last):

  File "v8function_handler_cef3.pyx", line 39, in cefpython_py27.V8FunctionHandler_Execute (cefpython.cpp:38833)

  File "C:\MMELC_pilot\python\wxpython_viewer.py", line 645, in get_updates
    url = get_endpoint()+'/api/v1.0/getUpdates'

NameError: global name 'get_endpoint' is not defined


[2017-12-18 17:07:28] Traceback (most recent call last):

  File "v8function_handler_cef3.pyx", line 39, in cefpython_py27.V8FunctionHandler_Execute (cefpython.cpp:38833)

  File "C:\MMELC_pilot\python\wxpython_viewer.py", line 645, in get_updates
    url = get_endpoint()+'/api/v1.0/getUpdates'

NameError: global name 'get_endpoint' is not defined


[2017-12-18 17:08:03] Traceback (most recent call last):

  File "v8function_handler_cef3.pyx", line 39, in cefpython_py27.V8FunctionHandler_Execute (cefpython.cpp:38833)

  File "C:\MMELC_pilot\python\wxpython_viewer.py", line 645, in get_updates
    url = get_endpoint()+'/api/v1.0/getUpdates'

NameError: global name 'get_endpoint' is not defined


[2017-12-18 17:08:21] Traceback (most recent call last):

  File "v8function_handler_cef3.pyx", line 39, in cefpython_py27.V8FunctionHandler_Execute (cefpython.cpp:38833)

  File "C:\MMELC_pilot\python\wxpython_viewer.py", line 645, in get_updates
    url = get_endpoint()+'/api/v1.0/getUpdates'

NameError: global name 'get_endpoint' is not defined


[2017-12-18 17:09:07] Traceback (most recent call last):

  File "v8function_handler_cef3.pyx", line 39, in cefpython_py27.V8FunctionHandler_Execute (cefpython.cpp:38833)

  File "C:\MMELC_pilot\python\wxpython_viewer.py", line 645, in get_updates
    url = get_endpoint() + '/api/v1.0/getUpdates'

NameError: global name 'get_endpoint' is not defined


[2017-12-18 17:09:59] Traceback (most recent call last):

  File "v8function_handler_cef3.pyx", line 39, in cefpython_py27.V8FunctionHandler_Execute (cefpython.cpp:38833)

  File "C:\MMELC_pilot\python\wxpython_viewer.py", line 645, in get_updates
    url = get_endpoint() #+ '/api/v1.0/getUpdates'

NameError: global name 'get_endpoint' is not defined


[2017-12-18 17:11:42] Traceback (most recent call last):

  File "v8function_handler_cef3.pyx", line 39, in cefpython_py27.V8FunctionHandler_Execute (cefpython.cpp:38833)

  File "C:\MMELC_pilot\python\wxpython_viewer.py", line 645, in get_updates
    url = str(get_endpoint()) + '/api/v1.0/getUpdates'

NameError: global name 'get_endpoint' is not defined


[2017-12-18 17:11:55] Traceback (most recent call last):

  File "v8function_handler_cef3.pyx", line 39, in cefpython_py27.V8FunctionHandler_Execute (cefpython.cpp:38833)

  File "C:\MMELC_pilot\python\wxpython_viewer.py", line 645, in get_updates
    url = str(get_endpoint()) + '/api/v1.0/getUpdates'

NameError: global name 'get_endpoint' is not defined


[2017-12-18 17:12:59] Traceback (most recent call last):

  File "v8function_handler_cef3.pyx", line 39, in cefpython_py27.V8FunctionHandler_Execute (cefpython.cpp:38833)

  File "C:\MMELC_pilot\python\wxpython_viewer.py", line 645, in get_updates
    ep = get_endpoint()

NameError: global name 'get_endpoint' is not defined


[2017-12-18 17:13:34] Traceback (most recent call last):

  File "v8function_handler_cef3.pyx", line 39, in cefpython_py27.V8FunctionHandler_Execute (cefpython.cpp:38833)

  File "C:\MMELC_pilot\python\wxpython_viewer.py", line 645, in get_updates
    ep = get_endpoint()

NameError: global name 'get_endpoint' is not defined


[2017-12-18 17:14:55] Traceback (most recent call last):

  File "v8function_handler_cef3.pyx", line 39, in cefpython_py27.V8FunctionHandler_Execute (cefpython.cpp:38833)

  File "C:\MMELC_pilot\python\wxpython_viewer.py", line 648, in get_updates
    ep = g_ep()

NameError: global name 'g_ep' is not defined


[2017-12-18 17:16:15] Traceback (most recent call last):

  File "v8function_handler_cef3.pyx", line 39, in cefpython_py27.V8FunctionHandler_Execute (cefpython.cpp:38833)

  File "C:\MMELC_pilot\python\wxpython_viewer.py", line 648, in get_updates
    ep = g_ep()

NameError: global name 'g_ep' is not defined


[2017-12-18 17:18:35] Traceback (most recent call last):

  File "v8function_handler_cef3.pyx", line 39, in cefpython_py27.V8FunctionHandler_Execute (cefpython.cpp:38833)

  File "C:\MMELC_pilot\python\wxpython_viewer.py", line 645, in get_updates
    url = get_endpoint() + '/api/v1.0/getUpdates'

NameError: global name 'get_endpoint' is not defined


[2017-12-18 17:19:55] Traceback (most recent call last):

  File "v8function_handler_cef3.pyx", line 39, in cefpython_py27.V8FunctionHandler_Execute (cefpython.cpp:38833)

  File "C:\MMELC_pilot\python\wxpython_viewer.py", line 645, in get_updates
    url = __self__.get_endpoint() + '/api/v1.0/getUpdates'

NameError: global name '__self__' is not defined


[2017-12-18 17:22:44] Traceback (most recent call last):

  File "v8function_handler_cef3.pyx", line 39, in cefpython_py27.V8FunctionHandler_Execute (cefpython.cpp:38833)

  File "C:\MMELC_pilot\python\wxpython_viewer.py", line 646, in get_updates
    url = get_endpoint() + '/api/v1.0/getUpdates'

TypeError: get_endpoint() takes exactly 1 argument (0 given)


[2017-12-18 18:13:20] Traceback (most recent call last):

  File "v8function_handler_cef3.pyx", line 39, in cefpython_py27.V8FunctionHandler_Execute (cefpython.cpp:38833)

  File "C:\MMELC_pilot\python\wxpython_viewer.py", line 658, in get_updates
    response = str(e.code()) + '::' + str(e)

TypeError: 'int' object is not callable


[2017-12-18 18:13:31] Traceback (most recent call last):

  File "v8function_handler_cef3.pyx", line 39, in cefpython_py27.V8FunctionHandler_Execute (cefpython.cpp:38833)

  File "C:\MMELC_pilot\python\wxpython_viewer.py", line 658, in get_updates
    response = str(e.code()) + '::' + str(e)

TypeError: 'int' object is not callable


[2017-12-18 18:14:18] Traceback (most recent call last):

  File "v8function_handler_cef3.pyx", line 39, in cefpython_py27.V8FunctionHandler_Execute (cefpython.cpp:38833)

  File "C:\MMELC_pilot\python\wxpython_viewer.py", line 658, in get_updates
    response = str(e.code()) + '::' + str(e)

TypeError: 'int' object is not callable


[2017-12-18 18:24:32] Traceback (most recent call last):

  File "v8function_handler_cef3.pyx", line 39, in cefpython_py27.V8FunctionHandler_Execute (cefpython.cpp:38833)

  File "C:\MMELC_pilot\python\wxpython_viewer.py", line 630, in send_error_reports
    with open(file_name+'.zip', 'b') as f:

ValueError: mode string must begin with one of 'r', 'w', 'a' or 'U', not 'b'


[2017-12-18 18:24:53] Traceback (most recent call last):

  File "v8function_handler_cef3.pyx", line 39, in cefpython_py27.V8FunctionHandler_Execute (cefpython.cpp:38833)

  File "C:\MMELC_pilot\python\wxpython_viewer.py", line 630, in send_error_reports
    with open(file_name+'.zip', 'b') as f:

ValueError: mode string must begin with one of 'r', 'w', 'a' or 'U', not 'b'


[2017-12-18 19:11:43] Traceback (most recent call last):

  File "v8function_handler_cef3.pyx", line 39, in cefpython_py27.V8FunctionHandler_Execute (cefpython.cpp:38833)

  File "C:\MMELC_pilot\python\wxpython_viewer.py", line 658, in get_updates
    response = str(e.code()) + '::' + str(e)

TypeError: 'int' object is not callable


[2017-12-18 19:12:01] Traceback (most recent call last):

  File "v8function_handler_cef3.pyx", line 39, in cefpython_py27.V8FunctionHandler_Execute (cefpython.cpp:38833)

  File "C:\MMELC_pilot\python\wxpython_viewer.py", line 658, in get_updates
    response = str(e.code()) + '::' + str(e)

TypeError: 'int' object is not callable


[2017-12-18 19:12:48] Traceback (most recent call last):

  File "v8function_handler_cef3.pyx", line 39, in cefpython_py27.V8FunctionHandler_Execute (cefpython.cpp:38833)

  File "C:\MMELC_pilot\python\wxpython_viewer.py", line 658, in get_updates
    response = str(e.code()) + '::' + str(e)

TypeError: 'int' object is not callable


[2017-12-18 19:14:47] Traceback (most recent call last):

  File "v8function_handler_cef3.pyx", line 39, in cefpython_py27.V8FunctionHandler_Execute (cefpython.cpp:38833)

  File "C:\MMELC_pilot\python\wxpython_viewer.py", line 658, in get_updates
    response = str(e.code()) + '::' + str(e)

TypeError: 'int' object is not callable


[2017-12-18 19:14:54] Traceback (most recent call last):

  File "v8function_handler_cef3.pyx", line 39, in cefpython_py27.V8FunctionHandler_Execute (cefpython.cpp:38833)

  File "C:\MMELC_pilot\python\wxpython_viewer.py", line 658, in get_updates
    response = str(e.code()) + '::' + str(e)

TypeError: 'int' object is not callable


[2017-12-18 19:16:39] Traceback (most recent call last):

  File "v8function_handler_cef3.pyx", line 39, in cefpython_py27.V8FunctionHandler_Execute (cefpython.cpp:38833)

  File "C:\MMELC_pilot\python\wxpython_viewer.py", line 658, in get_updates
    response = str(e.code()) + '::' + str(e)

TypeError: 'int' object is not callable


[2017-12-18 19:18:36] Traceback (most recent call last):

  File "v8function_handler_cef3.pyx", line 39, in cefpython_py27.V8FunctionHandler_Execute (cefpython.cpp:38833)

  File "C:\MMELC_pilot\python\wxpython_viewer.py", line 658, in get_updates
    response = str(e.code()) + '::' + str(e)

TypeError: 'int' object is not callable


[2017-12-18 19:21:47] Traceback (most recent call last):

  File "v8function_handler_cef3.pyx", line 39, in cefpython_py27.V8FunctionHandler_Execute (cefpython.cpp:38833)

  File "C:\MMELC_pilot\python\wxpython_viewer.py", line 661, in get_updates
    response = str(e.code()) + '::' + str(e)

TypeError: 'int' object is not callable


[2017-12-18 19:21:55] Traceback (most recent call last):

  File "v8function_handler_cef3.pyx", line 39, in cefpython_py27.V8FunctionHandler_Execute (cefpython.cpp:38833)

  File "C:\MMELC_pilot\python\wxpython_viewer.py", line 661, in get_updates
    response = str(e.code()) + '::' + str(e)

TypeError: 'int' object is not callable


[2017-12-21 17:06:24] Traceback (most recent call last):

  File "v8function_handler_cef3.pyx", line 39, in cefpython_py27.V8FunctionHandler_Execute (cefpython.cpp:38833)

  File "C:\MMELC_pilot\python\wxpython_viewer.py", line 622, in send_error_reports
    shutil.copytree(nginx_logs_dir, temp_loc)

  File "C:\MMELC_pilot\python\Python27\lib\shutil.py", line 177, in copytree
    os.makedirs(dst)

  File "C:\MMELC_pilot\python\Python27\lib\os.py", line 157, in makedirs
    mkdir(name, mode)

WindowsError: [Error 183] Cannot create a file when that file already exists: 'C:\\MMELC_pilot\\python\\temp_error_reports_loc'


[2017-12-21 17:10:35] Traceback (most recent call last):

  File "v8function_handler_cef3.pyx", line 39, in cefpython_py27.V8FunctionHandler_Execute (cefpython.cpp:38833)

  File "C:\MMELC_pilot\python\wxpython_viewer.py", line 623, in send_error_reports
    shutil.copytree(nginx_html_data_dir, temp_loc)

  File "C:\MMELC_pilot\python\Python27\lib\shutil.py", line 177, in copytree
    os.makedirs(dst)

  File "C:\MMELC_pilot\python\Python27\lib\os.py", line 157, in makedirs
    mkdir(name, mode)

WindowsError: [Error 183] Cannot create a file when that file already exists: 'C:\\MMELC_pilot\\python\\temp_error_reports_loc'


[2017-12-21 17:11:02] Traceback (most recent call last):

  File "v8function_handler_cef3.pyx", line 39, in cefpython_py27.V8FunctionHandler_Execute (cefpython.cpp:38833)

  File "C:\MMELC_pilot\python\wxpython_viewer.py", line 622, in send_error_reports
    shutil.copytree(nginx_logs_dir, temp_loc)

  File "C:\MMELC_pilot\python\Python27\lib\shutil.py", line 177, in copytree
    os.makedirs(dst)

  File "C:\MMELC_pilot\python\Python27\lib\os.py", line 157, in makedirs
    mkdir(name, mode)

WindowsError: [Error 183] Cannot create a file when that file already exists: 'C:\\MMELC_pilot\\python\\temp_error_reports_loc'

